+ source ../common_lib/fsio_lib.sh
++ source /root/mugen/libs/locallibs/common_lib.sh
+++ python3 --version
+++ '[' 0 -eq 0 ']'
+++ source /root/mugen/libs/locallibs/common_lib_python.sh
++ export 'FS_TYPE=ext3 ext4 xfs'
++ FS_TYPE='ext3 ext4 xfs'
++ export LANG=en_US.UTF-8
++ LANG=en_US.UTF-8
++ REMOVE_VG
++ vggroup=
++ [[ '' != '' ]]
+++ df -T
+++ grep test_vggroup
+++ awk '{print $7}'
++ mounted=
++ [[ '' != '' ]]
++ lsblk
++ grep test_vggroup
++ [[ 1 -eq 0 ]]
++ rm -rf '/tmp/point*'
+ main
++ type -t post_test
+ '[' -n function ']'
+ trap post_test EXIT INT HUP TERM
+ rpm -qa
+ grep expect
++ type -t config_params
+ '[' -n '' ']'
++ type -t pre_test
+ '[' -n function ']'
+ pre_test
+ LOG_INFO 'Start environment preparation.'
+ message='Start environment preparation.'
+ python3 /root/mugen/libs/locallibs/mugen_log.py --level info --message 'Start environment preparation.'
Mon Oct 16 23:14:11 2023 - INFO  - Start environment preparation.
++ date +%Y%m%d%H%M%S
+ cur_date=20231016231411
++ CREATE_VG
+++ date +%Y%m%d%H%M%S
++ cur_date=20231016231411
+++ lsblk
+++ grep disk
+++ awk '{print $1}'
+++ tail -n 1
++ free_disk=vde
++ disk_name=/dev/vde
++ pvcreate /dev/vde -f
++ [[ 5 -eq 0 ]]
+++ pvcreate /dev/vde
+++ grep test_vggroup
+++ cut -d '"' -f 4
++ vggroup=test_vggroup20231016222823
++ printf test_vggroup20231016222823
+ vggroup=test_vggroup20231016222823
+ ext4_point=/tmp/ext420231016231411
+ lvcreate -n test_lv120231016231411 -L 2G test_vggroup20231016222823 -y
  Volume group "test_vggroup20231016222823" has insufficient free space (124 extents): 512 required.
+ mkfs.ext4 /dev/test_vggroup20231016222823/test_lv120231016231411
mke2fs 1.47.0 (5-Feb-2023)
The file /dev/test_vggroup20231016222823/test_lv120231016231411 does not exist and no size was specified.
+ mkdir /tmp/ext420231016231411
++ ls /sys/fs/ext4
++ wc -l
+ origin=2
+ LOG_INFO 'End of environmental preparation!'
+ message='End of environmental preparation!'
+ python3 /root/mugen/libs/locallibs/mugen_log.py --level info --message 'End of environmental preparation!'
Mon Oct 16 23:14:12 2023 - INFO  - End of environmental preparation!
++ type -t run_test
+ '[' -n function ']'
+ run_test
+ LOG_INFO 'Start to run test.'
+ message='Start to run test.'
+ python3 /root/mugen/libs/locallibs/mugen_log.py --level info --message 'Start to run test.'
Mon Oct 16 23:14:13 2023 - INFO  - Start to run test.
+ mount /dev/test_vggroup20231016222823/test_lv120231016231411 /tmp/ext420231016231411
mount: /tmp/ext420231016231411: special device /dev/test_vggroup20231016222823/test_lv120231016231411 does not exist.
       dmesg(1) may have more information after failed mount system call.
+ CHECK_RESULT 32 0 0 'Mount failed.'
+ actual_result=32
+ expect_result=0
+ mode=0
+ error_log='Mount failed.'
+ exit_mode=0
+ '[' -z 32 ']'
+ '[' 0 -eq 0 ']'
+ test 32x '!=' 0x
+ test -n 'Mount failed.'
+ LOG_ERROR 'Mount failed.'
+ message='Mount failed.'
+ python3 /root/mugen/libs/locallibs/mugen_log.py --level error --message 'Mount failed.'
Mon Oct 16 23:14:13 2023 - ERROR - Mount failed.
+ (( exec_result++ ))
+ LOG_ERROR 'oe_test_FSIO_sys_fs_check.sh line 36'
+ message='oe_test_FSIO_sys_fs_check.sh line 36'
+ python3 /root/mugen/libs/locallibs/mugen_log.py --level error --message 'oe_test_FSIO_sys_fs_check.sh line 36'
Mon Oct 16 23:14:14 2023 - ERROR - oe_test_FSIO_sys_fs_check.sh line 36
+ '[' 0 -eq 1 ']'
+ return 0
++ ls /sys/fs/ext4
++ wc -l
+ actual=2
+ change=0
+ CHECK_RESULT 0 1 0 'Check change failed.'
+ actual_result=0
+ expect_result=1
+ mode=0
+ error_log='Check change failed.'
+ exit_mode=0
+ '[' -z 0 ']'
+ '[' 0 -eq 0 ']'
+ test 0x '!=' 1x
+ test -n 'Check change failed.'
+ LOG_ERROR 'Check change failed.'
+ message='Check change failed.'
+ python3 /root/mugen/libs/locallibs/mugen_log.py --level error --message 'Check change failed.'
Mon Oct 16 23:14:14 2023 - ERROR - Check change failed.
+ (( exec_result++ ))
+ LOG_ERROR 'oe_test_FSIO_sys_fs_check.sh line 39'
+ message='oe_test_FSIO_sys_fs_check.sh line 39'
+ python3 /root/mugen/libs/locallibs/mugen_log.py --level error --message 'oe_test_FSIO_sys_fs_check.sh line 39'
Mon Oct 16 23:14:15 2023 - ERROR - oe_test_FSIO_sys_fs_check.sh line 39
+ '[' 0 -eq 1 ']'
+ return 0
+ LOG_INFO 'End to run test.'
+ message='End to run test.'
+ python3 /root/mugen/libs/locallibs/mugen_log.py --level info --message 'End to run test.'
Mon Oct 16 23:14:15 2023 - INFO  - End to run test.
+ CASE_RESULT 0
+ case_re=0
+ test -z 2
+ test 2 -gt 0
+ LOG_ERROR 'failed to execute the case.'
+ message='failed to execute the case.'
+ python3 /root/mugen/libs/locallibs/mugen_log.py --level error --message 'failed to execute the case.'
Mon Oct 16 23:14:15 2023 - ERROR - failed to execute the case.
+ exit 2
+ post_test
+ LOG_INFO 'Start to restore the test environment.'
+ message='Start to restore the test environment.'
+ python3 /root/mugen/libs/locallibs/mugen_log.py --level info --message 'Start to restore the test environment.'
Mon Oct 16 23:14:16 2023 - INFO  - Start to restore the test environment.
+ umount -f /tmp/ext420231016231411
umount: /tmp/ext420231016231411: not mounted.
+ LOG_INFO 'End to restore the test environment.'
+ message='End to restore the test environment.'
+ python3 /root/mugen/libs/locallibs/mugen_log.py --level info --message 'End to restore the test environment.'
Mon Oct 16 23:14:16 2023 - INFO  - End to restore the test environment.
